<?xml version="1.0"?>
<robot xmlns:xacro="http://www.ros.org/wiki/xacro">

  <xacro:property name="prop_mesh" value="file://$(find stinger_description)/models/stinger_base/meshes/stinger_prop.dae"/>

  <xacro:macro name="prop_macro" params="thruster_id *origin">

    <link name="thruster_${thruster_id}"/>
    <joint name="thruster_joint_${thruster_id}" type="fixed">
      <xacro:insert_block name="origin"/>
      <parent link="base_link"/>
      <child link="thruster_${thruster_id}"/>
      <axis xyz="1 0 0"/>
    </joint>

    <link name="propeller_${thruster_id}">

      <!-- The inertial values need to be reasonable or gazebo will crash -->
      <inertial>
        <mass value="0.0000001" />
        <inertia ixx="0.00001" ixy="0.0" ixz="0.0"
                 iyy="0.00001" iyz="0.0" izz="0.000001" />
      </inertial>

      <visual>
        <origin xyz="0 0 0" rpy="0 -1.57 0"/>
        <geometry>
          <mesh filename="${prop_mesh}"/>
        </geometry>
      </visual>

    </link>

    <joint name="prop_joint_${thruster_id}" type="continuous">
      <parent link="thruster_${thruster_id}"/>
      <child link="propeller_${thruster_id}"/>
      <axis xyz="1 0 0"/>
    </joint>

    <!-- TODO: Get the correct values for these -->
    <gazebo>
      <plugin
        filename="gz-sim-thruster-system"
        name="gz::sim::systems::Thruster">
        <joint_name>prop_joint_${thruster_id}</joint_name>
        <thrust_coefficient>0.005</thrust_coefficient>
        <fluid_density>1000</fluid_density>
        <propeller_diameter>0.0594</propeller_diameter>
      </plugin>
    </gazebo>
  </xacro:macro>

</robot>